2025-09-07 15:33:37,083 |    ERROR | clever_ai | error:128 | [APP] Analysis failed | Error: 'types.SimpleNamespace' object has no attribute 'get'
2025-09-07 15:33:37,085 |    ERROR | clever_ai | error:129 | Traceback: Traceback (most recent call last):
  File "/workspaces/projects/app.py", line 451, in analyze
    debugger.debug('app', f'Analysis completed: {analysis.get("intent", "unknown")}')
                                                 ^^^^^^^^^^^^
AttributeError: 'types.SimpleNamespace' object has no attribute 'get'

2025-09-07 15:33:37,093 |    ERROR | clever_ai | error:128 | [CONVERSATION] Error in process_conversation | Data: {"duration": "0.0000s", "args_count": 5, "kwargs": []} | Error: 'types.SimpleNamespace' object has no attribute 'get'
2025-09-07 15:33:37,095 |    ERROR | clever_ai | error:129 | Traceback: Traceback (most recent call last):
  File "/workspaces/projects/debug_config.py", line 223, in wrapper
    result = func(*args, **kwargs)
             ^^^^^^^^^^^^^^^^^^^^^
  File "/workspaces/projects/clever_conversation_engine.py", line 110, in process_conversation
    response_approach = self._determine_response_approach(analysis, context)
                        ^^^^^^^^^^^^^^^^^^^^^^^^^^^^^^^^^^^^^^^^^^^^^^^^^^^^
  File "/workspaces/projects/clever_conversation_engine.py", line 142, in _determine_response_approach
    intent = analysis.get('intent', 'general')
             ^^^^^^^^^^^^
AttributeError: 'types.SimpleNamespace' object has no attribute 'get'

2025-09-07 15:33:37,099 |    ERROR | clever_ai | error:128 | [ERROR_RECOVERY] Error occurred | Data: {"context": {"endpoint": "/chat", "user_message": "hey clever"}} | Error: CleverPersona.generate_response() takes 2 positional arguments but 4 were given
2025-09-07 15:33:37,100 |    ERROR | clever_ai | error:129 | Traceback: Traceback (most recent call last):
  File "/workspaces/projects/app.py", line 182, in chat
    conversation_result = process_clever_conversation(user_message, analysis, context, knowledge_base)
                          ^^^^^^^^^^^^^^^^^^^^^^^^^^^^^^^^^^^^^^^^^^^^^^^^^^^^^^^^^^^^^^^^^^^^^^^^^^^^
  File "/workspaces/projects/clever_conversation_engine.py", line 627, in process_clever_conversation
    return engine.process_conversation(user_message, analysis, context, knowledge_base)
           ^^^^^^^^^^^^^^^^^^^^^^^^^^^^^^^^^^^^^^^^^^^^^^^^^^^^^^^^^^^^^^^^^^^^^^^^^^^^
  File "/workspaces/projects/debug_config.py", line 223, in wrapper
    result = func(*args, **kwargs)
             ^^^^^^^^^^^^^^^^^^^^^
  File "/workspaces/projects/clever_conversation_engine.py", line 110, in process_conversation
    response_approach = self._determine_response_approach(analysis, context)
                        ^^^^^^^^^^^^^^^^^^^^^^^^^^^^^^^^^^^^^^^^^^^^^^^^^^^^
  File "/workspaces/projects/clever_conversation_engine.py", line 142, in _determine_response_approach
    intent = analysis.get('intent', 'general')
             ^^^^^^^^^^^^
AttributeError: 'types.SimpleNamespace' object has no attribute 'get'

During handling of the above exception, another exception occurred:

Traceback (most recent call last):
  File "/workspaces/projects/app.py", line 196, in chat
    response = clever_persona.generate_response(user_message, USER_NAME, analysis)
               ^^^^^^^^^^^^^^^^^^^^^^^^^^^^^^^^^^^^^^^^^^^^^^^^^^^^^^^^^^^^^^^^^^^
TypeError: CleverPersona.generate_response() takes 2 positional arguments but 4 were given

2025-09-07 15:34:10,671 |    ERROR | clever_ai | error:128 | [APP] Analysis failed | Error: 'types.SimpleNamespace' object has no attribute 'get'
2025-09-07 15:34:10,673 |    ERROR | clever_ai | error:129 | Traceback: Traceback (most recent call last):
  File "/workspaces/projects/app.py", line 451, in analyze
    debugger.debug('app', f'Analysis completed: {analysis.get("intent", "unknown")}')
                                                 ^^^^^^^^^^^^
AttributeError: 'types.SimpleNamespace' object has no attribute 'get'

2025-09-07 15:34:10,675 |    ERROR | clever_ai | error:128 | [CONVERSATION] Error in process_conversation | Data: {"duration": "0.0000s", "args_count": 5, "kwargs": []} | Error: 'types.SimpleNamespace' object has no attribute 'get'
2025-09-07 15:34:10,676 |    ERROR | clever_ai | error:129 | Traceback: Traceback (most recent call last):
  File "/workspaces/projects/debug_config.py", line 223, in wrapper
    result = func(*args, **kwargs)
             ^^^^^^^^^^^^^^^^^^^^^
  File "/workspaces/projects/clever_conversation_engine.py", line 110, in process_conversation
    response_approach = self._determine_response_approach(analysis, context)
                        ^^^^^^^^^^^^^^^^^^^^^^^^^^^^^^^^^^^^^^^^^^^^^^^^^^^^
  File "/workspaces/projects/clever_conversation_engine.py", line 142, in _determine_response_approach
    intent = analysis.get('intent', 'general')
             ^^^^^^^^^^^^
AttributeError: 'types.SimpleNamespace' object has no attribute 'get'

2025-09-07 15:34:10,679 |    ERROR | clever_ai | error:128 | [ERROR_RECOVERY] Error occurred | Data: {"context": {"endpoint": "/chat", "user_message": "hey clev"}} | Error: CleverPersona.generate_response() takes 2 positional arguments but 4 were given
2025-09-07 15:34:10,681 |    ERROR | clever_ai | error:129 | Traceback: Traceback (most recent call last):
  File "/workspaces/projects/app.py", line 182, in chat
    conversation_result = process_clever_conversation(user_message, analysis, context, knowledge_base)
                          ^^^^^^^^^^^^^^^^^^^^^^^^^^^^^^^^^^^^^^^^^^^^^^^^^^^^^^^^^^^^^^^^^^^^^^^^^^^^
  File "/workspaces/projects/clever_conversation_engine.py", line 627, in process_clever_conversation
    return engine.process_conversation(user_message, analysis, context, knowledge_base)
           ^^^^^^^^^^^^^^^^^^^^^^^^^^^^^^^^^^^^^^^^^^^^^^^^^^^^^^^^^^^^^^^^^^^^^^^^^^^^
  File "/workspaces/projects/debug_config.py", line 223, in wrapper
    result = func(*args, **kwargs)
             ^^^^^^^^^^^^^^^^^^^^^
  File "/workspaces/projects/clever_conversation_engine.py", line 110, in process_conversation
    response_approach = self._determine_response_approach(analysis, context)
                        ^^^^^^^^^^^^^^^^^^^^^^^^^^^^^^^^^^^^^^^^^^^^^^^^^^^^
  File "/workspaces/projects/clever_conversation_engine.py", line 142, in _determine_response_approach
    intent = analysis.get('intent', 'general')
             ^^^^^^^^^^^^
AttributeError: 'types.SimpleNamespace' object has no attribute 'get'

During handling of the above exception, another exception occurred:

Traceback (most recent call last):
  File "/workspaces/projects/app.py", line 196, in chat
    response = clever_persona.generate_response(user_message, USER_NAME, analysis)
               ^^^^^^^^^^^^^^^^^^^^^^^^^^^^^^^^^^^^^^^^^^^^^^^^^^^^^^^^^^^^^^^^^^^
TypeError: CleverPersona.generate_response() takes 2 positional arguments but 4 were given

2025-09-07 15:34:15,377 |    ERROR | clever_ai | error:128 | [APP] Analysis failed | Error: 'types.SimpleNamespace' object has no attribute 'get'
2025-09-07 15:34:15,378 |    ERROR | clever_ai | error:129 | Traceback: Traceback (most recent call last):
  File "/workspaces/projects/app.py", line 451, in analyze
    debugger.debug('app', f'Analysis completed: {analysis.get("intent", "unknown")}')
                                                 ^^^^^^^^^^^^
AttributeError: 'types.SimpleNamespace' object has no attribute 'get'

2025-09-07 15:34:15,394 |    ERROR | clever_ai | error:128 | [CONVERSATION] Error in process_conversation | Data: {"duration": "0.0000s", "args_count": 5, "kwargs": []} | Error: 'types.SimpleNamespace' object has no attribute 'get'
2025-09-07 15:34:15,395 |    ERROR | clever_ai | error:129 | Traceback: Traceback (most recent call last):
  File "/workspaces/projects/debug_config.py", line 223, in wrapper
    result = func(*args, **kwargs)
             ^^^^^^^^^^^^^^^^^^^^^
  File "/workspaces/projects/clever_conversation_engine.py", line 110, in process_conversation
    response_approach = self._determine_response_approach(analysis, context)
                        ^^^^^^^^^^^^^^^^^^^^^^^^^^^^^^^^^^^^^^^^^^^^^^^^^^^^
  File "/workspaces/projects/clever_conversation_engine.py", line 142, in _determine_response_approach
    intent = analysis.get('intent', 'general')
             ^^^^^^^^^^^^
AttributeError: 'types.SimpleNamespace' object has no attribute 'get'

2025-09-07 15:34:15,396 |    ERROR | clever_ai | error:128 | [ERROR_RECOVERY] Error occurred | Data: {"context": {"endpoint": "/chat", "user_message": "hey"}} | Error: CleverPersona.generate_response() takes 2 positional arguments but 4 were given
2025-09-07 15:34:15,397 |    ERROR | clever_ai | error:129 | Traceback: Traceback (most recent call last):
  File "/workspaces/projects/app.py", line 182, in chat
    conversation_result = process_clever_conversation(user_message, analysis, context, knowledge_base)
                          ^^^^^^^^^^^^^^^^^^^^^^^^^^^^^^^^^^^^^^^^^^^^^^^^^^^^^^^^^^^^^^^^^^^^^^^^^^^^
  File "/workspaces/projects/clever_conversation_engine.py", line 627, in process_clever_conversation
    return engine.process_conversation(user_message, analysis, context, knowledge_base)
           ^^^^^^^^^^^^^^^^^^^^^^^^^^^^^^^^^^^^^^^^^^^^^^^^^^^^^^^^^^^^^^^^^^^^^^^^^^^^
  File "/workspaces/projects/debug_config.py", line 223, in wrapper
    result = func(*args, **kwargs)
             ^^^^^^^^^^^^^^^^^^^^^
  File "/workspaces/projects/clever_conversation_engine.py", line 110, in process_conversation
    response_approach = self._determine_response_approach(analysis, context)
                        ^^^^^^^^^^^^^^^^^^^^^^^^^^^^^^^^^^^^^^^^^^^^^^^^^^^^
  File "/workspaces/projects/clever_conversation_engine.py", line 142, in _determine_response_approach
    intent = analysis.get('intent', 'general')
             ^^^^^^^^^^^^
AttributeError: 'types.SimpleNamespace' object has no attribute 'get'

During handling of the above exception, another exception occurred:

Traceback (most recent call last):
  File "/workspaces/projects/app.py", line 196, in chat
    response = clever_persona.generate_response(user_message, USER_NAME, analysis)
               ^^^^^^^^^^^^^^^^^^^^^^^^^^^^^^^^^^^^^^^^^^^^^^^^^^^^^^^^^^^^^^^^^^^
TypeError: CleverPersona.generate_response() takes 2 positional arguments but 4 were given

